Workbook

Sheet 首页_总览
A1: LLM 应用开发工程师 · 14周就业执行计划 V2.1
A2: 目标：从“会跟课程做 Demo”升级为“能独立设计、编码、调试、评测、部署并通过面试”的 LLM Application Engineer。起始日：2026-09-24；98 天。V2.1 已融合八斗学院课程大纲中的高价值模块。 | N2: 周 | O2: 完成率
A3: V2.1 核心变化：吸收八斗的 Transformer/BERT 认知、ReAct、Memory、vLLM、FC/MCP/CLI、GraphRAG、故障转移等；继续保持“课程≤20% + 独立编码 + 实验 + 项目 + Code Review + 周测闯关”的主线。 | N3: 1 | O3: =G11 -> 0
A4: 核心指标 | B4: 当前 | C4: 目标 | D4: 说明 | F4: 使用规则 | J4: 执行状态 | K4: 天数 | L4: 占比 | N4: 周 | O4: 完成率
A5: 计划天数 | B5: =COUNTA(每日计划!$A$3:$A$100) -> 98 | C5: 98 | D5: 严格按每日计划执行 | F5: 1 | G5: 课程最多占20%，代码/项目占主导 | J5: 未开始 | K5: =COUNTIF(每日计划!$L$3:$L$100,J5) -> 98 | L5: =K5/$B$5 -> 1 | N5: 3 | O5: =G13 -> 0
A6: 计划有效学习时长 | B6: =SUM(每日计划!$M$3:$M$100) -> 812 | C6: 800 | D6: 工作日约8.5h，周日约7h | F6: 2 | G6: 每个知识点必须通过：知道→能写→能解释→能排障 | J6: 进行中 | K6: =COUNTIF(每日计划!$L$3:$L$100,J6) -> 0 | L6: =K6/$B$5 -> 0 | N6: 4 | O6: =G14 -> 0
A7: 毕业项目 | B7: =COUNTIF(V2_项目Review!$J$4:$J$9,"通过") -> 0 | C7: 3 | D7: 2个核心项目+1个旗舰项目 | F7: 3 | G7: 第9周开始求职，不等全部学完 | J7: 完成 | K7: =COUNTIF(每日计划!$L$3:$L$100,J7) -> 0 | L7: =K7/$B$5 -> 0 | N7: 5 | O7: =G15 -> 0
F8: 4 | G8: 每周日做周测，不通过就回补 | J8: 延期 | K8: =COUNTIF(每日计划!$L$3:$L$100,J8) -> 0 | L8: =K8/$B$5 -> 0 | N8: 6 | O8: =G16 -> 0
F9: 5 | G9: 毕业标准看“能否独立完成/解释”，不是看视频进度 | N9: 7 | O9: =G17 -> 0
A10: 14周阶段 | B10: 核心能力 | C10: 周交付物 | D10: 验收闸门 | E10: 课程 | F10: 状态 | G10: 完成率 | N10: 8 | O10: =G18 -> 0
A11: 1 | B11: Python 工程 + FastAPI + HTTP/SSE + pytest | C11: 项目1 v0：LLM Chat API（FastAPI + SSE + Pydantic + pytest） | D11: 不看视频，60–90分钟从空目录写出 /chat、/health、SSE、基础异常处理。 | E11: C1/C2/C3 | F11: =IF(G11=1,"完成",IF(COUNTIF(每日计划!$L$3:$L$9,"进行中")>0,"进行中","未开始")) -> 未开始 | G11: =COUNTIF(每日计划!$L$3:$L$9,"完成")/7 -> 0 | N11: 9 | O11: =G19 -> 0
A12: 2 | B12: LLM API + Prompt + Structured Output + Tool Calling 入门 | C12: 项目1 v1：AI 内容分析服务 + 原生 Tool Calling Loop | D12: 能解释消息角色、token、temperature；能自己实现 JSON Schema 输出和工具调用循环。 | E12: C1/C2/C4/C7 | F12: =IF(G12=1,"完成",IF(COUNTIF(每日计划!$L$10:$L$16,"进行中")>0,"进行中","未开始")) -> 未开始 | G12: =COUNTIF(每日计划!$L$10:$L$16,"完成")/7 -> 0 | N12: 10 | O12: =G20 -> 0
A13: 3 | B13: 文档 → Chunk → Embedding → 相似度 → TopK | C13: RAG Lab 1：纯 Python + Embedding API 的最小检索器 | D13: 能解释 cosine/dot product/TopK/Recall@K，并能故意构造 3 种召回失败案例。 | E13: C1/C4/C7 | F13: =IF(G13=1,"完成",IF(COUNTIF(每日计划!$L$17:$L$23,"进行中")>0,"进行中","未开始")) -> 未开始 | G13: =COUNTIF(每日计划!$L$17:$L$23,"完成")/7 -> 0 | N13: 11 | O13: =G21 -> 0
A14: 4 | B14: LangChain + Vector DB + Metadata + Retriever + BM25 | C14: RAG Lab 2：可上传文档、metadata 过滤、dense + BM25 | D14: 能在 15 分钟画出完整 RAG 架构，并解释每一层为什么存在。 | E14: C2/C4/C7 | F14: =IF(G14=1,"完成",IF(COUNTIF(每日计划!$L$24:$L$30,"进行中")>0,"进行中","未开始")) -> 未开始 | G14: =COUNTIF(每日计划!$L$24:$L$30,"完成")/7 -> 0 | N14: 12 | O14: =G22 -> 0
A15: 5 | B15: Hybrid Search + Rerank + Query Rewrite + Citation + Evaluation | C15: RAG Eval v1：100 条评测集 + Recall/Precision/回答质量对比 | D15: 至少完成 3 轮实验并有可复现结果；能解释每次优化改变了什么。 | E15: C1/C4/C6 | F15: =IF(G15=1,"完成",IF(COUNTIF(每日计划!$L$31:$L$37,"进行中")>0,"进行中","未开始")) -> 未开始 | G15: =COUNTIF(每日计划!$L$31:$L$37,"完成")/7 -> 0 | N15: 13 | O15: =G23 -> 0
A16: 6 | B16: 企业知识库：React + FastAPI + PostgreSQL/pgvector + Redis + RAG | C16: 项目2 v1：企业知识库系统（上传/解析/检索/引用/Streaming） | D16: 从空项目独立完成核心链路；Docker 能一键启动基础环境。 | E16: C2/C6/C7 | F16: =IF(G16=1,"完成",IF(COUNTIF(每日计划!$L$38:$L$44,"进行中")>0,"进行中","未开始")) -> 未开始 | G16: =COUNTIF(每日计划!$L$38:$L$44,"完成")/7 -> 0 | N16: 14 | O16: =G24 -> 0
A17: 7 | B17: Tool Calling + Workflow + State | C17: Agent Lab：天气/计算器/HTTP API/数据库查询 4 个工具 | D17: 能手写 tool-call loop；能解释 agent 与 workflow 的边界。 | E17: C1/C4/C6 | F17: =IF(G17=1,"完成",IF(COUNTIF(每日计划!$L$45:$L$51,"进行中")>0,"进行中","未开始")) -> 未开始 | G17: =COUNTIF(每日计划!$L$45:$L$51,"完成")/7 -> 0
A18: 8 | B18: State/Node/Edge/Conditional/Checkpoint/HITL | C18: 项目3 v1：企业 AI 助手（RAG + DB Tool + API Tool + Workflow） | D18: 能画状态图；能处理异常分支、重试和中断后恢复。 | E18: C2/C4/C6 | F18: =IF(G18=1,"完成",IF(COUNTIF(每日计划!$L$52:$L$58,"进行中")>0,"进行中","未开始")) -> 未开始 | G18: =COUNTIF(每日计划!$L$52:$L$58,"完成")/7 -> 0
A19: 9 | B19: MCP Server/Client + 工具暴露 + 简历第一版 + GitHub/作品集 | C19: 项目3 v2：自建 MCP Server；简历 v1；GitHub README/架构图 | D19: 至少 1 个 MCP Server 被 Agent 成功调用；完成第一批岗位定向投递。 | E19: C6/C4/C3 | F19: =IF(G19=1,"完成",IF(COUNTIF(每日计划!$L$59:$L$65,"进行中")>0,"进行中","未开始")) -> 未开始 | G19: =COUNTIF(每日计划!$L$59:$L$65,"完成")/7 -> 0
A20: 10 | B20: PostgreSQL + Redis + asyncio + Docker + 鉴权/限流/日志 | C20: 项目3 v3：鉴权/缓存/日志/异常/测试/Docker Compose | D20: 能解释连接池、缓存、异步、幂等、限流；能独立定位一次接口故障。 | E20: C2/C6/C3 | F20: =IF(G20=1,"完成",IF(COUNTIF(每日计划!$L$66:$L$72,"进行中")>0,"进行中","未开始")) -> 未开始 | G20: =COUNTIF(每日计划!$L$66:$L$72,"完成")/7 -> 0 | N20: 每日执行：看主线资源≤90min → 关教程空目录重写 → 实验/故障演练 → 合入项目 → 提交我做 Code Review → 修改重构 → 周测。
A21: 11 | B21: 离线评测 + 自动回归 + Trace + Token/Cost/Latency | C21: Evaluation/Observability 模块：dataset + metrics + trace + report | D21: 修改 RAG 配置后能自动跑回归，并生成前后版本对比结果。 | E21: C4/C6/C3 | F21: =IF(G21=1,"完成",IF(COUNTIF(每日计划!$L$73:$L$79,"进行中")>0,"进行中","未开始")) -> 未开始 | G21: =COUNTIF(每日计划!$L$73:$L$79,"完成")/7 -> 0
A22: 12 | B22: Ollama + vLLM + OpenAI-compatible API + 模型解耦 | C22: Model Gateway：至少两个模型后端可切换；本地模型服务跑通 | D22: 应用代码不绑定单一模型供应商；能解释 vLLM 的定位和基本部署方式。 | E22: C4/C5/C6 | F22: =IF(G22=1,"完成",IF(COUNTIF(每日计划!$L$80:$L$86,"进行中")>0,"进行中","未开始")) -> 未开始 | G22: =COUNTIF(每日计划!$L$80:$L$86,"完成")/7 -> 0
A23: 13 | B23: 企业 AI 工作助手 0→1：需求/架构/实现/评测/部署/文档 | C23: 旗舰项目 RC：RAG + Agent + MCP + DB + Redis + Eval + Trace + Docker | D23: 能从需求出发独立讲完整技术方案、权衡、故障案例和优化结果。 | E23: C2/C4/C6/C3 | F23: =IF(G23=1,"完成",IF(COUNTIF(每日计划!$L$87:$L$93,"进行中")>0,"进行中","未开始")) -> 未开始 | G23: =COUNTIF(每日计划!$L$87:$L$93,"完成")/7 -> 0
A24: 14 | B24: 项目精修 + 面试 + 简历 + 投递 + 模拟面试 | C24: 简历 v2 + 项目演示 + 30题核心面试题 + 3轮模拟面试 + 定向投递 | D24: 能在 30 分钟内完整讲项目，并回答 Python/RAG/Agent/工程化追问。 | E24: C3/C1/C4 | F24: =IF(G24=1,"完成",IF(COUNTIF(每日计划!$L$94:$L$100,"进行中")>0,"进行中","未开始")) -> 未开始 | G24: =COUNTIF(每日计划!$L$94:$L$100,"完成")/7 -> 0

Sheet 每日计划
A1: 98天每日执行表 V2.1（每天打开这里执行；已加入八斗大纲融合任务） | R1: V2.1 八斗融合提醒
A2: Day | B2: 日期 | C2: 周 | D2: 星期 | E2: 阶段 | F2: 本周重点 | G2: 优先级 | H2: 今日必须完成 | I2: 今日产出 | J2: 课程索引 | K2: 验收标准 | L2: 状态 | M2: 计划小时 | N2: 实际记录/备注 | O2: 推荐资源ID | P2: 主线学习资源 | Q2: 学习链接 | R2: 本列只在相关 Day 强化八斗大纲中的高价值知识；没有内容的天保持主线。
A3: 1 | B3: 46289 | C3: 1 | D3: 周四 | E3: 基础重建 | F3: Python 工程 + FastAPI + HTTP/SSE + pytest | G3: 🔴 | H3: Python 工程复盘：typing/dataclass/Pydantic/异常；建立 uv 项目骨架 | I3: 创建 pyproject、.env、logging、配置模块；提交 git | J3: C1/C2 | K3: 能空目录搭工程并解释每个目录 | L3: 未开始 | M3: 8.5 | O3: R01/R03/R07/R08 | P3: R01 · Python 官方 Tutorial | Q3: https://docs.python.org/3/tutorial/
A4: 2 | B4: 46290 | C4: 1 | D4: 周五 | E4: 基础重建 | F4: Python 工程 + FastAPI + HTTP/SSE + pytest | G4: 🔴 | H4: HTTP/REST 基础：请求响应、状态码、JSON、SSE 概念 | I4: 写 /health、/echo、/chat 三个接口 | J4: C2 | K4: Postman/curl 可调用；错误码合理 | L4: 未开始 | M4: 8.5 | O4: R02 | P4: R02 · FastAPI 官方 Tutorial | Q4: https://fastapi.tiangolo.com/tutorial/
A5: 3 | B5: 46291 | C5: 1 | D5: 周六 | E5: 基础重建 | F5: Python 工程 + FastAPI + HTTP/SSE + pytest | G5: 🔴 | H5: FastAPI：依赖注入、Pydantic schema、异常处理 | I5: 实现请求参数校验与统一异常响应 | J5: C2/C3 | K5: 坏参数不会让服务崩；响应结构稳定 | L5: 未开始 | M5: 8.5 | O5: R02/R03 | P5: R02 · FastAPI 官方 Tutorial | Q5: https://fastapi.tiangolo.com/tutorial/
A6: 4 | B6: 46292 | C6: 1 | D6: 周日 | E6: 基础重建 | F6: Python 工程 + FastAPI + HTTP/SSE + pytest | G6: 🔴 | H6: asyncio/httpx：async/await、并发请求、timeout | I6: 实现异步模型客户端 + timeout/retry | J6: C1/C4 | K6: 连续请求 10 次无阻塞；能解释 await | L6: 未开始 | M6: 7 | O6: R04/R05 | P6: R04 · Python asyncio 官方文档 | Q6: https://docs.python.org/3/library/asyncio.html
A7: 5 | B7: 46293 | C7: 1 | D7: 周一 | E7: 基础重建 | F7: Python 工程 + FastAPI + HTTP/SSE + pytest | G7: 🔴 | H7: SSE：StreamingResponse、断线、心跳 | I7: 实现模拟 token 流；浏览器/前端可消费 | J7: C2 | K7: 可持续推送；客户端结束能释放资源 | L7: 未开始 | M7: 8.5 | O7: R02 | P7: R02 · FastAPI 官方 Tutorial | Q7: https://fastapi.tiangolo.com/tutorial/
A8: 6 | B8: 46294 | C8: 1 | D8: 周二 | E8: 基础重建 | F8: Python 工程 + FastAPI + HTTP/SSE + pytest | G8: 🔴 | H8: pytest：单测、mock、API 测试 | I8: 覆盖 health/chat/schema/error 关键路径 | J8: C3 | K8: 至少 10 个测试；pytest 全绿 | L8: 未开始 | M8: 8.5 | O8: R06 | P8: R06 · pytest 官方文档 | Q8: https://docs.pytest.org/en/stable/
A9: 7 | B9: 46295 | C9: 1 | D9: 周三 | E9: 基础重建 | F9: Python 工程 + FastAPI + HTTP/SSE + pytest | G9: 🔴 | H9: 周测：不看课程从 0 重写 Chat API；总结 10 个坑 | I9: 提交 README + 架构图 + 复盘 | J9: C1/C2 | K9: 90 分钟完成核心版本；能口述架构 | L9: 未开始 | M9: 8.5 | O9: R09 | P9: R09 · DataTalksClub LLM Zoomcamp 2026 | Q9: https://courses.datatalks.club/llm-zoomcamp-2026/
A10: 8 | B10: 46296 | C10: 2 | D10: 周四 | E10: LLM 应用基础 | F10: LLM API + Prompt + Structured Output + Tool Calling 入门 | G10: 🔴 | H10: LLM API：system/user/assistant、temperature、max tokens | I10: 原生 SDK 实现单轮/多轮对话 | J10: C1/C4 | K10: 能解释参数影响；支持历史消息 | L10: 未开始 | M10: 8.5 | O10: R10 | P10: R10 · OpenAI Cookbook | Q10: https://cookbook.openai.com/
A11: 9 | B11: 46297 | C11: 2 | D11: 周五 | E11: LLM 应用基础 | F11: LLM API + Prompt + Structured Output + Tool Calling 入门 | G11: 🔴 | H11: Streaming 深入：chunk、累计、前端展示 | I11: 把真实模型流接入 FastAPI SSE | J11: C2 | K11: 首 token 与结束事件可记录 | L11: 未开始 | M11: 8.5 | O11: R02/R10 | P11: R02 · FastAPI 官方 Tutorial | Q11: https://fastapi.tiangolo.com/tutorial/
A12: 10 | B12: 46298 | C12: 2 | D12: 周六 | E12: LLM 应用基础 | F12: LLM API + Prompt + Structured Output + Tool Calling 入门 | G12: 🔴 | H12: Structured Output：JSON Schema/Pydantic | I12: 实现文本分类+抽取服务 | J12: C1/C4 | K12: 输出可解析；失败自动重试 | L12: 未开始 | M12: 8.5 | O12: R03/R10 | P12: R03 · Pydantic 官方文档 | Q12: https://docs.pydantic.dev/latest/
A13: 11 | B13: 46299 | C13: 2 | D13: 周日 | E13: LLM 应用基础 | F13: LLM API + Prompt + Structured Output + Tool Calling 入门 | G13: 🔴 | H13: Prompt：任务拆解、约束、Few-shot、上下文组织 | I13: 建立 prompt 模板与版本记录 | J13: C1/C3 | K13: 同一任务多版本对比并记录差异 | L13: 未开始 | M13: 7 | O13: R10 | P13: R10 · OpenAI Cookbook | Q13: https://cookbook.openai.com/
A14: 12 | B14: 46300 | C14: 2 | D14: 周一 | E14: LLM 应用基础 | F14: LLM API + Prompt + Structured Output + Tool Calling 入门 | G14: 🔴 | H14: Tool Calling：tool schema、arguments、tool result | I14: 实现 calculator/weather 两个工具 | J14: C4/C6 | K14: 能完成一次完整 tool-call loop | L14: 未开始 | M14: 8.5 | O14: R10 | P14: R10 · OpenAI Cookbook | Q14: https://cookbook.openai.com/
... A16: 14 | B16: 46302 | C16: 2 | D16: 周三 | E16: LLM 应用基础 | F16: LLM API + Prompt + Structured Output + Tool Calling 入门 | G16: 🔴 | H16: 周测：脱离 LangChain 写 Chat + JSON + Tool Calling | I16: 录制 5 分钟讲解并提交代码 | J16: C1/C4 | K16: 面试官追问底层时能答 | L16: 未开始 | M16: 8.5 | O16: R09/R10 | P16: R09 · DataTalksClub LLM Zoomcamp 2026 | Q16: https://courses.datatalks.club/llm-zoomcamp-2026/
A17: 15 | B17: 46303 | C17: 3 | D17: 周四 | E17: RAG 原理 | F17: 文档 → Chunk → Embedding → 相似度 → TopK | G17: 🔴 | H17: Embedding：token→vector；BGE/BGE-M3 基本用法 | I17: 做 20 句文本 embedding 实验 | J17: C1/C4/C7 | K17: 观察维度、归一化、相似度 | L17: 未开始 | M17: 8.5 | O17: R13/R12 | P17: R13 · FlagEmbedding / BGE | Q17: https://github.com/FlagOpen/FlagEmbedding | R17: 八斗：Embedding / Pooling / Norm；补充“为什么 embedding 能表达语义”的解释。
A18: 16 | B18: 46304 | C18: 3 | D18: 周五 | E18: RAG 原理 | F18: 文档 → Chunk → Embedding → 相似度 → TopK | G18: 🔴 | H18: 相似度：cosine/dot product/L2 | I18: 手写 top-k 相似度搜索 | J18: C4/C7 | K18: 能解释归一化后 dot 的关系 | L18: 未开始 | M18: 8.5 | O18: R12 | P18: R12 · Sentence Transformers Semantic Search | Q18: https://www.sbert.net/examples/sentence_transformer/applications/semantic-search/README.html | R18: 八斗：Sentence-BERT / FAISS 认知；理解向量检索为何可做近邻搜索。
A19: 17 | B19: 46305 | C19: 3 | D19: 周六 | E19: RAG 原理 | F19: 文档 → Chunk → Embedding → 相似度 → TopK | G19: 🔴 | H19: Chunk：固定长度、overlap、按语义/标题切 | I19: 准备 3 种 chunk 策略并跑同一评测集 | J19: C1/C4 | K19: 记录 chunk 对召回的影响 | L19: 未开始 | M19: 8.5 | O19: R11/R13 | P19: R11 · LangChain RAG from Scratch | Q19: https://github.com/langchain-ai/rag-from-scratch | R19: 八斗：语义分块与 NLP 文本结构；记录不同 chunk 策略的 trade-off。
A20: 18 | B20: 46306 | C20: 3 | D20: 周日 | E20: RAG 原理 | F20: 文档 → Chunk → Embedding → 相似度 → TopK | G20: 🔴 | H20: Retriever：TopK、召回候选与上下文 | I20: 实现基础检索器 + metadata | J20: C2/C7 | K20: 能查到来源文档位置 | L20: 未开始 | M20: 7 | O20: R11/R14 | P20: R11 · LangChain RAG from Scratch | Q20: https://github.com/langchain-ai/rag-from-scratch
A21: 19 | B21: 46307 | C21: 3 | D21: 周一 | E21: RAG 原理 | F21: 文档 → Chunk → Embedding → 相似度 → TopK | G21: 🔴 | H21: RAG Prompt：context 注入、引用、拒答 | I21: 实现最小 RAG QA | J21: C2/C7 | K21: 不知道答案时不胡编；带引用 | L21: 未开始 | M21: 8.5 | O21: R11 | P21: R11 · LangChain RAG from Scratch | Q21: https://github.com/langchain-ai/rag-from-scratch
A22: 20 | B22: 46308 | C22: 3 | D22: 周二 | E22: RAG 原理 | F22: 文档 → Chunk → Embedding → 相似度 → TopK | G22: 🔴 | H22: RAG Failure Lab：故意制造错召回 | I22: 记录至少 3 个失败案例和原因 | J22: C4 | K22: 能从数据/切片/embedding/topK 排查 | L22: 未开始 | M22: 8.5 | O22: R11 | P22: R11 · LangChain RAG from Scratch | Q22: https://github.com/langchain-ai/rag-from-scratch | R22: 八斗：RAG 失败分析思维；用“检索错/排序错/生成错”三分法定位问题。
A23: 21 | B23: 46309 | C23: 3 | D23: 周三 | E23: RAG 原理 | F23: 文档 → Chunk → Embedding → 相似度 → TopK | G23: 🔴 | H23: 周测：从文档到答案完全重写最小 RAG | I23: 不看教程完成；写设计说明 | J23: C1/C4 | K23: 60–120 分钟跑通 | L23: 未开始 | M23: 8.5 | O23: R09/R11 | P23: R09 · DataTalksClub LLM Zoomcamp 2026 | Q23: https://courses.datatalks.club/llm-zoomcamp-2026/
A24: 22 | B24: 46310 | C24: 4 | D24: 周四 | E24: RAG 工程 | F24: LangChain + Vector DB + Metadata + Retriever + BM25 | G24: 🔴 | H24: LangChain 核心：Runnable、|、Parallel、Passthrough | I24: 把手写链迁移到 LangChain | J24: C4/C7 | K24: 能解释抽象而非背代码 | L24: 未开始 | M24: 8.5 | O24: R11 | P24: R11 · LangChain RAG from Scratch | Q24: https://github.com/langchain-ai/rag-from-scratch | R24: 八斗：知识点迁移；把 LangChain 抽象和底层 Python 逻辑对应起来。
A25: 23 | B25: 46311 | C25: 4 | D25: 周五 | E25: RAG 工程 | F25: LangChain + Vector DB + Metadata + Retriever + BM25 | G25: 🔴 | H25: Vector DB：collection、index、metadata filter | I25: 选一个向量库完成 CRUD + search | J25: C2 | K25: 能解释 schema 与过滤 | L25: 未开始 | M25: 8.5 | O25: R14 | P25: R14 · pgvector | Q25: https://github.com/pgvector/pgvector
A26: 24 | B26: 46312 | C26: 4 | D26: 周六 | E26: RAG 工程 | F26: LangChain + Vector DB + Metadata + Retriever + BM25 | G26: 🔴 | H26: Document Loader/Parser：PDF/Word/网页/纯文本 | I26: 做统一文档 ingestion 接口 | J26: C2/C6 | K26: 至少支持 PDF + txt/docx 中 2 类 | L26: 未开始 | M26: 8.5 | O26: R27 | P26: R27 · Unstructured OSS Docs | Q26: https://docs.unstructured.io/open-source/introduction/overview
A27: 25 | B27: 46313 | C27: 4 | D27: 周日 | E27: RAG 工程 | F27: LangChain + Vector DB + Metadata + Retriever + BM25 | G27: 🔴 | H27: Metadata：来源、页码、标题、权限 | I27: 在 chunk 上附 metadata | J27: C2/C6 | K27: 检索结果能追溯原文 | L27: 未开始 | M27: 7 | O27: R14/R27 | P27: R14 · pgvector | Q27: https://github.com/pgvector/pgvector
A28: 26 | B28: 46314 | C28: 4 | D28: 周一 | E28: RAG 工程 | F28: LangChain + Vector DB + Metadata + Retriever + BM25 | G28: 🔴 | H28: BM25：关键词检索 + dense retrieval | I28: 实现/接入 BM25，比较两种召回 | J28: C4 | K28: 给出 5 个适合 BM25 的问题 | L28: 未开始 | M28: 8.5 | O28: R28 | P28: R28 · rank_bm25 | Q28: https://github.com/dorianbrown/rank_bm25 | R28: 八斗：BM25 + dense retrieval；理解关键词检索与语义检索的互补。
A29: 27 | B29: 46315 | C29: 4 | D29: 周二 | E29: RAG 工程 | F29: LangChain + Vector DB + Metadata + Retriever + BM25 | G29: 🔴 | H29: Hybrid Search：融合策略 | I29: 实现 dense+BM25 融合 baseline | J29: C4/C6 | K29: 评测集上可对比前后效果 | L29: 未开始 | M29: 8.5 | O29: R11/R28 | P29: R11 · LangChain RAG from Scratch | Q29: https://github.com/langchain-ai/rag-from-scratch
A30: 28 | B30: 46316 | C30: 4 | D30: 周三 | E30: RAG 工程 | F30: LangChain + Vector DB + Metadata + Retriever + BM25 | G30: 🔴 | H30: 周测：画出并讲清 RAG 全链路 | I30: 15 分钟白板讲解 + 10 道追问 | J30: C3/C4 | K30: 至少 8/10 能回答 | L30: 未开始 | M30: 8.5 | O30: R09/R11 | P30: R09 · DataTalksClub LLM Zoomcamp 2026 | Q30: https://courses.datatalks.club/llm-zoomcamp-2026/
A31: 29 | B31: 46317 | C31: 5 | D31: 周四 | E31: RAG 优化 | F31: Hybrid Search + Rerank + Query Rewrite + Citation + Evaluation | G31: 🔴 | H31: Rerank 原理与接入：候选集→重排→TopN | I31: 加入 reranker 实验 | J31: C4/C6 | K31: 能解释为何不是直接 TopN vector | L31: 未开始 | M31: 8.5 | O31: R13/R11 | P31: R13 · FlagEmbedding / BGE | Q31: https://github.com/FlagOpen/FlagEmbedding | R31: 八斗：CrossEncoder / Rerank；理解二阶段检索为什么存在。
A32: 30 | B32: 46318 | C32: 5 | D32: 周五 | E32: RAG 优化 | F32: Hybrid Search + Rerank + Query Rewrite + Citation + Evaluation | G32: 🔴 | H32: Query Rewrite：上下文补全、拆问题、多查询 | I32: 对多轮问题做 rewrite | J32: C1/C4 | K32: 解决 5 个上下文省略问题 | L32: 未开始 | M32: 8.5 | O32: R11 | P32: R11 · LangChain RAG from Scratch | Q32: https://github.com/langchain-ai/rag-from-scratch
A33: 31 | B33: 46319 | C33: 5 | D33: 周六 | E33: RAG 优化 | F33: Hybrid Search + Rerank + Query Rewrite + Citation + Evaluation | G33: 🔴 | H33: Metadata/权限过滤：用户/部门/文档类型 | I33: 在检索前后加入权限过滤 | J33: C2/C6 | K33: 不会把无权限内容返回 | L33: 未开始 | M33: 8.5 | O33: R25/R14 | P33: R25 · OWASP Top 10 for LLM Applications | Q33: https://owasp.org/www-project-top-10-for-large-language-model-applications/
A34: 32 | B34: 46320 | C34: 5 | D34: 周日 | E34: RAG 优化 | F34: Hybrid Search + Rerank + Query Rewrite + Citation + Evaluation | G34: 🔴 | H34: Context Compression：去冗余、窗口控制 | I34: 实现简单压缩/去重策略 | J34: C4 | K34: Context token 降低且答案不恶化 | L34: 未开始 | M34: 7 | O34: R11 | P34: R11 · LangChain RAG from Scratch | Q34: https://github.com/langchain-ai/rag-from-scratch
A35: 33 | B35: 46321 | C35: 5 | D35: 周一 | E35: RAG 优化 | F35: Hybrid Search + Rerank + Query Rewrite + Citation + Evaluation | G35: 🔴 | H35: Citation/grounding：引用位置与证据链 | I35: 实现前端引用展示数据结构 | J35: C2/C6 | K35: 每个答案引用至少 1 个证据 | L35: 未开始 | M35: 8.5 | O35: R11 | P35: R11 · LangChain RAG from Scratch | Q35: https://github.com/langchain-ai/rag-from-scratch
A36: 34 | B36: 46322 | C36: 5 | D36: 周二 | E36: RAG 优化 | F36: Hybrid Search + Rerank + Query Rewrite + Citation + Evaluation | G36: 🔴 | H36: Evaluation：构造 100 条问题+标准答案 | I36: 计算 Recall@K/Precision 等基础指标 | J36: C4 | K36: 一键生成 JSON/CSV 报告 | L36: 未开始 | M36: 8.5 | O36: R22/R21 | P36: R22 · Ragas | Q36: https://docs.ragas.io/
A37: 35 | B37: 46323 | C37: 5 | D37: 周三 | E37: RAG 优化 | F37: Hybrid Search + Rerank + Query Rewrite + Citation + Evaluation | G37: 🔴 | H37: 周测：三轮实验 + RAG 失败分析报告 | I37: Baseline→Hybrid→Rerank 三版本对比 | J37: C4/C6 | K37: 能明确说出优化收益和代价 | L37: 未开始 | M37: 8.5 | O37: R21/R22 | P37: R21 · DeepLearning.AI · Evaluating AI Agents | Q37: https://www.deeplearning.ai/short-courses/evaluating-ai-agents/ | R37: 八斗：RAG 评测；用数据证明优化，而不是凭感觉。
A38: 36 | B38: 46324 | C38: 6 | D38: 周四 | E38: 完整项目1 | F38: 企业知识库：React + FastAPI + PostgreSQL/pgvector + Redis + RAG | G38: 🔴 | H38: 项目2 需求：用户/知识库/文档/会话/引用模型设计 | I38: 画 DB schema + API 清单 | J38: C2 | K38: 表结构/API 可评审 | L38: 未开始 | M38: 8.5 | O38: R15/R14 | P38: R15 · PostgreSQL Tutorial | Q38: https://www.postgresql.org/docs/current/tutorial.html
A39: 37 | B39: 46325 | C39: 6 | D39: 周五 | E39: 完整项目1 | F39: 企业知识库：React + FastAPI + PostgreSQL/pgvector + Redis + RAG | G39: 🔴 | H39: 项目2 后端骨架：FastAPI + PostgreSQL + Redis | I39: 完成 auth/session/doc 基础模块 | J39: C2/C6 | K39: 服务可启动；迁移可执行 | L39: 未开始 | M39: 8.5 | O39: R02/R15/R16 | P39: R02 · FastAPI 官方 Tutorial | Q39: https://fastapi.tiangolo.com/tutorial/
A40: 38 | B40: 46326 | C40: 6 | D40: 周六 | E40: 完整项目1 | F40: 企业知识库：React + FastAPI + PostgreSQL/pgvector + Redis + RAG | G40: 🔴 | H40: 项目2 ingestion：上传、解析、chunk、embedding | I40: 跑通异步入库流程 | J40: C2/C6 | K40: 文档处理失败可重试/记录 | L40: 未开始 | M40: 8.5 | O40: R27/R13 | P40: R27 · Unstructured OSS Docs | Q40: https://docs.unstructured.io/open-source/introduction/overview
A41: 39 | B41: 46327 | C41: 6 | D41: 周日 | E41: 完整项目1 | F41: 企业知识库：React + FastAPI + PostgreSQL/pgvector + Redis + RAG | G41: 🔴 | H41: 项目2 retrieval：vector + metadata + hybrid | I41: 实现检索 API | J41: C4 | K41: 有 query/filters/topK 参数 | L41: 未开始 | M41: 7 | O41: R14/R11 | P41: R14 · pgvector | Q41: https://github.com/pgvector/pgvector
...

Sheet 周计划
A1: 14周周计划 · 每周日做一次“闸门验收”
A2: 周 | B2: 阶段 | C2: 核心重点 | D2: 本周目标 | E2: 必须交付 | F2: 闸门验收 | G2: 建议课程 | H2: 求职动作
A3: 1 | B3: 基础重建 | C3: Python 工程 + FastAPI + HTTP/SSE + pytest | D3: 能独立写一个可测试、可流式输出的 LLM Chat API，不依赖课程代码。 | E3: 项目1 v0：LLM Chat API（FastAPI + SSE + Pydantic + pytest） | F3: 不看视频，60–90分钟从空目录写出 /chat、/health、SSE、基础异常处理。 | G3: C1/C2/C3 | H3: 只学习/建项目基础
A4: 2 | B4: LLM 应用基础 | C4: LLM API + Prompt + Structured Output + Tool Calling 入门 | D4: 能脱离 LangChain 直接调用模型，处理流式、多轮、结构化输出和基础 Tool Calling。 | E4: 项目1 v1：AI 内容分析服务 + 原生 Tool Calling Loop | F4: 能解释消息角色、token、temperature；能自己实现 JSON Schema 输出和工具调用循环。 | G4: C1/C2/C4/C7 | H4: 建立技术词汇表
A5: 3 | B5: RAG 原理 | C5: 文档 → Chunk → Embedding → 相似度 → TopK | D5: 手写一个最小 RAG，真正理解检索链路和失败原因。 | E5: RAG Lab 1：纯 Python + Embedding API 的最小检索器 | F5: 能解释 cosine/dot product/TopK/Recall@K，并能故意构造 3 种召回失败案例。 | G5: C1/C4/C7 | H5: 开始收集目标岗位JD
A6: 4 | B6: RAG 工程 | C6: LangChain + Vector DB + Metadata + Retriever + BM25 | D6: 把手写 RAG 迁移到工程框架，理解抽象层而不是背 API。 | E6: RAG Lab 2：可上传文档、metadata 过滤、dense + BM25 | F6: 能在 15 分钟画出完整 RAG 架构，并解释每一层为什么存在。 | G6: C2/C4/C7 | H6: 记录高频面试问题
A7: 5 | B7: RAG 优化 | C7: Hybrid Search + Rerank + Query Rewrite + Citation + Evaluation | D7: 从“能回答”升级到“能测量、能优化、能解释为什么变好”。 | E7: RAG Eval v1：100 条评测集 + Recall/Precision/回答质量对比 | F7: 至少完成 3 轮实验并有可复现结果；能解释每次优化改变了什么。 | G7: C1/C4/C6 | H7: 建立作品集证据
A8: 6 | B8: 完整项目1 | C8: 企业知识库：React + FastAPI + PostgreSQL/pgvector + Redis + RAG | D8: 形成第一份可展示作品，贯通前后端和 RAG。 | E8: 项目2 v1：企业知识库系统（上传/解析/检索/引用/Streaming） | F8: 从空项目独立完成核心链路；Docker 能一键启动基础环境。 | G8: C2/C6/C7 | H8: 完善项目README
A9: 7 | B9: Agent 基础 | C9: Tool Calling + Workflow + State | D9: 不依赖框架理解 Agent Loop，能把多个工具组织成可控流程。 | E9: Agent Lab：天气/计算器/HTTP API/数据库查询 4 个工具 | F9: 能手写 tool-call loop；能解释 agent 与 workflow 的边界。 | G9: C1/C4/C6 | H9: 开始练项目讲解
A10: 8 | B10: LangGraph | C10: State/Node/Edge/Conditional/Checkpoint/HITL | D10: 能设计并实现可恢复、可调试的多步骤 Agent Workflow。 | E10: 项目3 v1：企业 AI 助手（RAG + DB Tool + API Tool + Workflow） | F10: 能画状态图；能处理异常分支、重试和中断后恢复。 | G10: C2/C4/C6 | H10: 准备简历素材
A11: 9 | B11: MCP + 求职启动 | C11: MCP Server/Client + 工具暴露 + 简历第一版 + GitHub/作品集 | D11: 完成 MCP 闭环，同时开始投递而不是等全部学完。 | E11: 项目3 v2：自建 MCP Server；简历 v1；GitHub README/架构图 | F11: 至少 1 个 MCP Server 被 Agent 成功调用；完成第一批岗位定向投递。 | G11: C6/C4/C3 | H11: 开始正式投递
A12: 10 | B12: 工程化 | C12: PostgreSQL + Redis + asyncio + Docker + 鉴权/限流/日志 | D12: 把项目从 Demo 提升到可维护后端服务。 | E12: 项目3 v3：鉴权/缓存/日志/异常/测试/Docker Compose | F12: 能解释连接池、缓存、异步、幂等、限流；能独立定位一次接口故障。 | G12: C2/C6/C3 | H12: 每周复盘投递反馈
A13: 11 | B13: Evaluation + Observability | C13: 离线评测 + 自动回归 + Trace + Token/Cost/Latency | D13: 形成“效果可量化、问题可定位”的 AI 工程能力。 | E13: Evaluation/Observability 模块：dataset + metrics + trace + report | F13: 修改 RAG 配置后能自动跑回归，并生成前后版本对比结果。 | G13: C4/C6/C3 | H13: 针对JD补缺口
A14: 12 | B14: 模型服务 | C14: Ollama + vLLM + OpenAI-compatible API + 模型解耦 | D14: 理解应用层与推理服务解耦，能切换云模型/本地模型。 | E14: Model Gateway：至少两个模型后端可切换；本地模型服务跑通 | F14: 应用代码不绑定单一模型供应商；能解释 vLLM 的定位和基本部署方式。 | G14: C4/C5/C6 | H14: 继续定向投递
... A16: 14 | B16: 求职冲刺 | C16: 项目精修 + 面试 + 简历 + 投递 + 模拟面试 | D16: 停止堆新技术，集中转化为面试表现与 Offer 机会。 | E16: 简历 v2 + 项目演示 + 30题核心面试题 + 3轮模拟面试 + 定向投递 | F16: 能在 30 分钟内完整讲项目，并回答 Python/RAG/Agent/工程化追问。 | G16: C3/C1/C4 | H16: 集中面试/投递

Sheet 知识地图
A1: 知识地图 V2.1 · 学到什么程度就停
A2: 领域 | B2: 知识点 | C2: 优先级 | D2: 目标层级 | E2: 必须做到 | F2: 暂不深挖 | G2: 建议周
A3: Python/后端 | B3: Python 核心语法、typing、装饰器、生成器 | C3: 🔴必学 | D3: 会写+会解释 | E3: 能读懂并修改正常 Python 服务 | F3: 底层解释器源码 | G3: 1
A4: Python/后端 | B4: asyncio/async/await/httpx | C4: 🔴必学 | D4: 能写+能排障 | E4: 能处理并发 IO/timeout/retry | F4: 底层事件循环源码 | G4: 1,10
A5: Python/后端 | B5: FastAPI/Pydantic | C5: 🔴必学 | D5: 能独立开发 | E5: REST/SSE/依赖注入/异常/测试 | F5: 框架源码细节 | G5: 1,10
A6: 数据库 | B6: PostgreSQL/SQL/索引/事务 | C6: 🔴必学 | D6: 会用+会解释 | E6: 能设计常用表与查询 | F6: DBA深度 | G6: 10
A7: 缓存 | B7: Redis | C7: 🔴必学 | D7: 会用+会解释 | E7: 缓存/session/限流 | F7: Redis源码 | G7: 10
A8: LLM | B8: Token/Context/Temperature/Structured Output | C8: 🔴必学 | D8: 能讲清原理+会用 | E8: 能解释参数、失败模式 | F8: 模型训练细节 | G8: 2
A9: LLM | B9: Transformer/Attention/Hidden State | C9: 🟠重点 | D9: 能用自己的话解释 | E9: 不推导全部论文 | F9: 完整训练数学 | G9: 2,14
A10: RAG | B10: Chunk/Embedding/Similarity/TopK | C10: 🔴必学 | D10: 能手写+能排障 | E10: 能定位召回问题 | F10: Embedding训练 | G10: 3-5
A11: RAG | B11: Vector DB/Metadata | C11: 🔴必学 | D11: 能独立接入 | E11: CRUD/search/filter | F11: 数据库内核 | G11: 4
A12: RAG | B12: BM25/Hybrid/Rerank | C12: 🟠重点 | D12: 能实现+能解释 | E12: 能做实验并对比 | F12: 检索学术论文深挖 | G12: 4-5
A13: RAG | B13: Query Rewrite/Compression/Citation | C13: 🟠重点 | D13: 能实现+能评测 | E13: 能解决多轮和上下文问题 | F13: 复杂GraphRAG | G13: 5
... A30: 工程 | B30: API高可用：Retry/Fallback/Health/Circuit Breaker | C30: 🔴必学 | D30: 能实现+故障注入 | E30: 至少完成1次完整故障演练 | F30: 大规模服务治理 | G30: 10

Sheet 项目与毕业标准
A1: 项目与毕业标准 · 不满足验收，不算学会
A2: 项目 | B2: 目标 | C2: 核心模块 | D2: 必须功能 | E2: 工程要求 | F2: 证据 | G2: 毕业前状态 | H2: 验收
A3: 项目1｜LLM Chat API | B3: 展示 Python 后端基本功 | C3: FastAPI/async/SSE/LLM API/Pydantic/pytest | D3: 多轮、Streaming、结构化输出、基础Tool Calling | E3: 错误处理、日志、测试、env、Docker基础 | F3: GitHub代码+README+测试截图 | G3: 必须完成 | H3: 能脱离教程 90 分钟重写核心
A4: 项目2｜企业知识库 | B4: 展示 RAG 深度与前后端全栈 | C4: React/FastAPI/PostgreSQL/pgvector/Redis/RAG | D4: 文档上传、解析、Chunk、Hybrid、Rerank、引用、SSE | E4: 权限/缓存/重试/测试/Docker | F4: Demo+架构图+评测报告 | G4: 必须完成 | H4: 100条以上评测集，有优化前后对比
A5: 项目3｜企业AI助手/Agent | B5: 展示 Agent/MCP/工程化 | C5: LangGraph/Tool Calling/MCP/DB Tool/API Tool/RAG | D5: 路由、Workflow、HITL、记忆、工具、引用 | E5: Trace、token/cost、异常、权限、审计、Docker | F5: 10分钟Demo+30分钟答辩 | G5: 必须完成 | H5: 能讲清trade-off与故障处理
A6: 毕业项A｜Python后端 | B6: 基础能力 | C6: Python/FastAPI/async/SQL/Redis | D6: 独立写接口+测试 | E6: 结构清晰/可维护 | F6: 现场编码 | G6: 合格 | H6: 面试手写题不依赖AI
A7: 毕业项B｜RAG | B7: 核心AI能力 | C7: Embedding/Retrieval/Hybrid/Rerank/Eval | D7: 能优化召回 | E7: 有数据驱动对比 | F7: 实验报告 | G7: 合格 | H7: 能回答“60%准确率怎么提升”
A8: 毕业项C｜Agent | B8: 核心AI能力 | C8: Tool/Workflow/LangGraph/MCP | D8: 多工具流程+安全 | E8: 失败可恢复 | F8: 状态图+代码 | G8: 合格 | H8: 能白板设计复杂Agent
A9: 毕业项D｜工程化 | B9: 真实工作能力 | C9: Docker/Logging/Observability/Model Gateway | D9: 可部署/可排障 | E9: 有runbook | F9: 部署文档 | G9: 合格 | H9: 能解释线上故障定位
A10: 毕业项E｜求职 | B10: 转化能力 | C10: 简历/作品集/面试/投递 | D10: 定向投递+模拟面 | E10: 不夸大、不编造 | F10: 简历+投递表 | G10: 合格 | H10: 能把每个亮点落到代码或数据

Sheet 课程索引
A1: 课程索引 · 把课程当“知识仓库”，不要线性刷课
A2: 索引 | B2: 课程 | C2: 定位 | D2: 优先主题 | E2: 使用原则 | F2: 链接
A3: C1 | B3: 【知乎知客堂】182809_知乎AI应用开发工程师大模型15期 | C3: 补充主线知识；按主题查课，不线性刷完 | D3: Python/LLM/RAG/Agent/就业 | E3: 出现知识缺口时再看对应章节；看完立即关视频自己实现
A4: C2 | B4: 【尚硅谷】AI 大模型全栈系列实战课｜0 基础到项目落地 | C4: 全栈工程与完整项目参考 | D4: FastAPI/数据库/RAG/Agent/部署 | E4: 出现知识缺口时再看对应章节；看完立即关视频自己实现
A5: C3 | B5: 【博学谷】AI大模型就业班（第八期） | C5: 就业/面试体系补充 | D5: 面试/项目/工程化 | E5: 出现知识缺口时再看对应章节；看完立即关视频自己实现
A6: C4 | B6: 【极客时间】AI大模型应用开发实战营第7期 | C6: 深度理解与应用设计 | D6: RAG/Agent/工程化/原理 | E6: 出现知识缺口时再看对应章节；看完立即关视频自己实现
A7: C5 | B7: 【九天菜菜】大模型原理与训练实战 | C7: 后段原理与微调补充，不作为前期主线 | D7: Transformer/训练/SFT/LoRA | E7: 出现知识缺口时再看对应章节；看完立即关视频自己实现
A8: C6 | B8: 【聚客AI】2026AI大模型工程师实战营六期 全栈开发教程 | C8: 补充 Agent/MCP/全栈/新技术 | D8: Agent/MCP/部署/工程化 | E8: 出现知识缺口时再看对应章节；看完立即关视频自己实现
A9: C7 | B9: 【黑马-B站】AI大模型RAG与Agent智能体开发项目课程 | C9: 已学完；只用于快速回查 | D9: RAG/Agent | E9: 出现知识缺口时再看对应章节；看完立即关视频自己实现 | F9: https://www.bilibili.com/video/BV1yjz5BLEoY/?spm_id_from=333.337.search-card.all.click&vd_source=772c334c2324a49a603567162bb9f37e
A10: V2.1课程策略 | B10: 八斗大纲 | C10: 对照/补充 | D10: 按 V2.1_八斗融合评估执行 | E10: 不线性刷完整套课 | F10: 用户提供截图
A11: V2.1课程策略 | B11: Bilibili Agent实战课 | C11: 补充 | D11: 重点挑 LangGraph / Skills / GraphRAG / 企业项目 | E11: 不替代主线 | F11: R32
A12: V2.1课程策略 | B12: Hysen AI工程实战课 | C12: 补充 | D12: Transformer/KV Cache/LoRA/vLLM/毕业项目 | E12: 只补缺口 | F12: R33
A13: V2.1原则 | B13: 所有录播 | C13: 限制 | D13: 只看指定章节；看完立即关视频独立重写 | E13: 禁止“看完再练” | F13: 执行依据

Sheet 每日节奏
A1: 每日节奏 V2.1 · 以输出为中心
A2: 时间 | B2: 内容 | C2: 目标 | D2: 执行规则 | E2: 周日调整 | F2: 完成标记
A3: 08:00–09:00 | B3: 复习 + 原理 | C3: 把昨天内容讲一遍 | D3: 先回忆，后看资料 | E3: 08:00–09:30 做周测复盘 | F3: □
A4: 09:00–12:00 | B4: 手写代码 | C4: 完成当日核心编码 | D4: 禁止照抄；先写再查 | E4: 09:30–12:00 补弱项 | F4: □
A5: 12:00–13:30 | B5: 午饭/休息 | C5: 恢复精力 | D5: 不安排重学习 | E5: 12:00–13:30 休息 | F5: □
A6: 13:30–15:00 | B6: 课程查缺 | C6: 只看今天需要的章节 | D6: 课程占全天≤20% | E6: 13:30–15:00 周总结 | F6: □
A7: 15:00–17:30 | B7: 项目实战 | C7: 把知识进入项目 | D7: 必须产生 Git commit | E7: 15:00–17:00 项目整理 | F7: □
A8: 17:30–18:00 | B8: 休息 | C8: 放空 | D8: 不补课 | E8: 17:00–17:30 休息 | F8: □
A9: V2.1 强制规则：课程≤20%；每个核心知识点必须经历“知道→能写→能解释→能排障”；每周至少一次独立重写；八斗新增内容只能在对应 Day 加深，不得因为大纲更长而无限扩张学习周期。 | B9: 面试/复盘 | C9: 当天至少回答5题 | D9: 写下不会的问题 | E9: 17:30–18:30 周测讲解；18:30–19:00 计划下周 | F9: □

Sheet 求职与面试
A1: 求职与面试节奏 · 第9周开始正式投递
A2: 周 | B2: 求职目标 | C2: 简历/作品集 | D2: 面试训练 | E2: 投递动作 | F2: 复盘内容 | G2: 核心产出 | H2: 完成
A3: 1 | B3: 了解岗位 | C3: 建立目标岗位JD池 | D3: Python基础词汇 | E3: 收藏10个岗位 | F3: 记录高频要求 | G3: JD表 | H3: 未开始
A4: 2 | B4: 确定技术主线 | C4: 建立简历素材库 | D4: LLM基础题 | E4: 收藏10个 | F4: 归类RAG/Agent/后端要求 | G4: 要求地图 | H4: 未开始
A5: 3 | B5: 建立岗位标准 | C5: 项目素材开始积累 | D5: RAG基础题 | E5: 开始记录JD | F5: 统计共性技能 | G5: 岗位技能表 | H5: 未开始
A6: 4 | B6: 验证岗位匹配 | C6: 项目截图/代码证据 | D6: RAG深挖题 | E6: 筛选岗位 | F6: 记录缺口 | G6: 岗位匹配表 | H6: 未开始
A7: 5 | B7: 形成作品集 | C7: 项目2开始出稿 | D7: RAG/评测题 | E7: 准备定向投递 | F7: 看岗位是否要MCP/Agent | G7: 作品集v0 | H7: 未开始
A8: 6 | B8: 简历素材成型 | C8: 项目2 README | D8: 项目讲解5分钟 | E8: 预留目标公司列表 | F8: 优化量化描述 | G8: 简历素材库 | H8: 未开始
A9: 7 | B9: 模拟面试 | C9: 项目讲解稿 | D9: Python+RAG模拟 | E9: 准备投递 | F9: 记录弱项 | G9: 模拟记录1 | H9: 未开始
A10: 8 | B10: 准备启动 | C10: 简历v1 | D10: Agent/系统设计 | E10: 建立20岗清单 | F10: 按JD排序缺口 | G10: 简历v1 | H10: 未开始
A11: 9 | B11: 正式投递 | C11: 简历v1+GitHub | D11: 2次模拟 | E11: 第一批10–20个定向投递 | F11: 分析回复率 | G11: 投递表v1 | H11: 未开始
A12: 10 | B12: 继续投递 | C12: 按JD微调项目表述 | D12: Python/后端 | E12: 10–20个定向投递 | F12: 记录面试题 | G12: 面试错题本 | H12: 未开始
A13: 11 | B13: 补缺口 | C13: 加入评测/Trace证据 | D13: RAG/工程面试 | E13: 继续定向投递 | F13: 针对拒绝原因补齐 | G13: 简历v2素材 | H13: 未开始
A14: 12 | B14: 增强技术深度 | C14: 模型服务证据 | D14: vLLM/部署题 | E14: 继续投递 | F14: 筛选更匹配岗位 | G14: 项目v3 | H14: 未开始
... A16: 14 | B16: 面试/Offer阶段 | C16: 简历v2 | D16: 3轮模拟+复盘 | E16: 集中投递与面试 | F16: 每场后更新错题 | G16: 最终材料包 | H16: 未开始

Sheet 岗位需求依据
A1: 2026年9月岗位需求抽样 · 用来校准学习重点
A2: 来源 | B2: 时间/地区 | C2: 岗位要点 | D2: 对本计划的影响 | E2: URL
A3: 百度校园招聘｜上海-大模型研发工程师 | B3: 2026-07-21｜上海 | C3: Python、LLM API、RAG、Agent、vLLM/LangChain、Docker/K8s、大模型应用系统研发 | D3: 证明主干必须覆盖 Python + RAG/Agent + 模型服务 + 容器化 | E3: https://talent.baidu.com/jobs/detail/GRADUATE/3b3888c3-5d8b-4c62-9bbb-a142c24e7d86
A4: 上海人工智能实验室｜大模型应用算法工程师 | B4: 2026-08-13｜上海 | C4: Python/PyTorch、RAG、Agent、Prompt、模型训练/部署；偏算法/工程混合 | D4: 作为较高门槛参考；训练/微调放在加分项而非主线 | E4: https://www.shlab.org.cn/joinus/detail/7540111744543443250?mode=social
A5: 上海复易｜大模型应用开发工程师 | B5: 2026-09-17｜上海 | C5: Python/FastAPI/异步、LLM API、Prompt/RAG/Agent、Redis、云部署 | D5: 强化 FastAPI + asyncio + Redis + 云部署 | E5: https://m.yupao.com/zhaogong/345327801.html
A6: 上海超级线索｜AI大模型应用开发工程师 | B6: 近期｜上海 | C6: 全栈AI应用、RAG、Agent、向量库、Linux/Git/Docker、微调、开源/独立Demo | D6: 强化你的前端优势，要求全链路与工程化 | E6: https://www.zhaopin.com/jobdetail/CCL1518858530J40885152310.htm
A7: AI Agent研发工程师｜上海 | B7: 2026-07-14｜上海 | C7: Agent架构、RAG、Prompt、记忆、缓存/MQ/异步、可观测与安全 | D7: 强化 Agent 工程化、安全、可观测性 | E7: https://career.muc.edu.cn/front/zwxx.jspa?xqzwId=37668&zpxxId=31784
A8: 大模型应用工程师｜上海 | B8: 近期｜上海 | C8: RAG/Agent、LangGraph/LlamaIndex/Dify、Function Calling、JSON Schema、流式、Redis、异步、MQ、Docker、评测 | D8: 直接对应本计划的高级工程能力 | E8: https://www.zhaopin.com/jobdetail/CC167420220J40934637212.htm

Sheet V2_资源库
A1: V2.1 · 精选学习资源库（主线资源优先 + 八斗大纲融合）
A2: 使用规则：主线优先官方/项目方 + 有实战/作业的资源；录播只看指定章节。课程时间≤20%，其余用于独立编码、实验、项目、Review。
A3: 八斗学院大纲来自你提供的课程截图；其内容作为能力补充与项目对照，不代表我们要求完整照单学习。
A4: ID | B4: 类型 | C4: 资源名称 | D4: 级别 | E4: 推荐周 | F4: 重点章节 / 学习动作 | G4: 为什么纳入 | H4: 链接 | I4: 备注
A5: R01 | B5: 官方教程 | C5: Python 官方 Tutorial | D5: 主线 | E5: 1 | F5: 基础语法回顾、数据结构、模块、异常；不从头刷完整教程。 | G5: Python 已有基础，只补缺口 | H5: https://docs.python.org/3/tutorial/ | I5: Python 已有基础，只补缺口
A6: R02 | B6: 官方教程 | C6: FastAPI 官方 Tutorial | D6: 主线 | E6: 1/6/10 | F6: Path/Query、Pydantic、依赖注入、异常、Streaming、Testing。 | G6: 以官方文档为 API 事实来源 | H6: https://fastapi.tiangolo.com/tutorial/ | I6: 以官方文档为 API 事实来源
A7: R03 | B7: 官方文档 | C7: Pydantic 官方文档 | D7: 主线 | E7: 1/2 | F7: BaseModel、validation、Settings、typing。 | G7: 只查与当前任务相关的部分 | H7: https://docs.pydantic.dev/latest/ | I7: 只查与当前任务相关的部分
A8: R04 | B8: 官方文档 | C8: Python asyncio 官方文档 | D8: 主线 | E8: 1/10 | F8: async/await、Task、gather、timeout、并发边界。 | G8: 理解异步机制，不死记 API | H8: https://docs.python.org/3/library/asyncio.html | I8: 理解异步机制，不死记 API
A9: R05 | B9: 官方文档 | C9: HTTPX Async 官方文档 | D9: 主线 | E9: 1/10 | F9: AsyncClient、连接复用、timeout、并发请求。 | G9: 替代同步 requests 的工程实践 | H9: https://www.python-httpx.org/async/ | I9: 替代同步 requests 的工程实践
A10: R06 | B10: 官方文档 | C10: pytest 官方文档 | D10: 主线 | E10: 1/10 | F10: fixtures、mock、parametrize、API testing。 | G10: 至少做到能写/改/定位测试 | H10: https://docs.pytest.org/en/stable/ | I10: 至少做到能写/改/定位测试
A11: R07 | B11: 课程/教程 | C11: MIT Missing Semester | D11: 补充 | E11: 1/10 | F11: 命令行、Shell、Git、Debug、工具链。 | G11: 只补工程习惯，不追求全学完 | H11: https://missing.csail.mit.edu/ | I11: 只补工程习惯，不追求全学完
A12: R08 | B12: 书/教程 | C12: Pro Git | D12: 补充 | E12: 1/9/14 | F12: 分支、commit、rebase、远程仓库协作基础。 | G12: 重点是能规范管理项目历史 | H12: https://git-scm.com/book/en/v2 | I12: 重点是能规范管理项目历史
A13: R09 | B13: 课程 | C13: DataTalksClub LLM Zoomcamp 2026 | D13: 主线 | E13: 2/3/4/5/13/14 | F13: LLM/RAG/Agentic RAG/Evaluation/Monitoring；重点做 Homework + Project。 | G13: 作为“作业驱动”主线资源之一 | H13: https://courses.datatalks.club/llm-zoomcamp-2026/ | I13: 作为“作业驱动”主线资源之一
A14: R10 | B14: 官方 Cookbook | C14: OpenAI Cookbook | D14: 主线 | E14: 2/7 | F14: Structured Outputs、Tool Calling、Streaming、应用模式。 | G14: 模型厂商可替换，重点学模式而非绑定厂商 | H14: https://cookbook.openai.com/ | I14: 模型厂商可替换，重点学模式而非绑定厂商
A15: R11 | B15: 实战项目 | C15: LangChain RAG from Scratch | D15: 主线 | E15: 3/4/5/6 | F15: 从检索基础到高级 RAG 的实验材料。 | G15: 先理解，再迁移到工程项目 | H15: https://github.com/langchain-ai/rag-from-scratch | I15: 先理解，再迁移到工程项目
... A37: R33 | B37: 实战课程 | C37: AI 工程实战课：从调用大模型到亲手写一个 GPT | D37: 补充 | E37: 2/12 | F37: Transformer、小 GPT、KV Cache、LoRA、量化、Ollama/vLLM、毕业项目。 | G37: 用于补原理与模型服务，不改变应用开发主线。 | H37: https://hysenlabs.com/zh-cn/course | I37: 课程页当前显示长期有效；具体价格/可见课时以页面为准

Sheet V2_项目Review
A1: V2.1 · 实战项目 + Code Review + 毕业验收
A2: V2.1 新增：八斗项目映射、ReAct/Memory/FC-MCP-CLI、API高可用、vLLM性能与GraphRAG高级实验。提交时必须附 README、关键代码、测试/评测结果与设计说明。
A3: ID | B3: 项目阶段 | C3: 项目名称 | D3: 核心能力 | E3: 必须功能 | F3: 加分项 | G3: 交付物 | H3: Review重点 | I3: 毕业标准 | J3: 状态 | K3: 备注
A4: L1 | B4: Lab | C4: RAG Lab 1 · 最小检索器 | D4: Embedding / similarity / TopK | E4: 文本→embedding→TopK→来源 | F4: 3种chunk策略+实验报告 | G4: 代码+实验表+设计说明 | H4: 向量、归一化、召回逻辑、异常 | I4: 能从空目录独立重写 | J4: 未开始 | K4: 不允许直接复制课程代码
A5: L2 | B5: Lab | C5: RAG Eval Lab · 检索优化 | D5: Hybrid / Rerank / Evaluation | E5: Dense、BM25、Hybrid、Rerank 对比 | F5: 100–300条评测集+版本对比 | G5: JSON/CSV报告+曲线/表格 | H5: 指标设计是否合理、结论是否可信 | I5: 能用数据解释优化收益/代价 | J5: 未开始 | K5: 这是简历的重要证据
A6: P1 | B6: 项目1 | C6: LLM Chat API | D6: FastAPI / SSE / LLM API / pytest | E6: /chat、/health、Streaming、错误处理、测试 | F6: Tool Calling、Token统计、Retry/Timeout | G6: GitHub仓库+README+测试 | H6: API设计、async、异常、测试 | I6: 90分钟从空目录写核心版 | J6: 未开始 | K6: 第1–2周
A7: P2 | B7: 项目2 | C7: 企业知识库系统 | D7: RAG / PostgreSQL / pgvector / Redis / React | E7: 上传、解析、chunk、embedding、检索、引用、SSE | F7: Hybrid、Rerank、权限、评测 | G7: 可运行 Demo+架构图+部署 | H7: 数据模型、检索链路、前后端联调 | I7: 陌生人照README能跑 | J7: 未开始 | K7: 第6周
A8: A1 | B8: 项目3 | C8: Agent + MCP 企业AI助手 | D8: Tool Calling / LangGraph / MCP | E8: RAG + DB Tool + API Tool + Workflow + MCP | F8: HITL、Trace、安全策略 | G8: 演示视频+时序图+测试 | H8: State、路由、失败处理、MCP边界 | I8: 能白板设计并回答20问 | J8: 未开始 | K8: 第7–9周
A9: P3 | B9: 旗舰项目 | C9: 企业 AI 工作助手 RC | D9: 全栈 + RAG + Agent + MCP + Eval + Trace | E9: 需求→架构→实现→测试→评测→部署 | F9: 模型解耦、成本优化、回归、审计 | G9: 完整README+架构图+评测报告+Demo | H9: trade-off、故障案例、性能、可维护性 | I9: 30分钟完整答辩 | J9: 未开始 | K9: 第13–14周
A12: 提交给我 Review 的最小材料
A13: 1 | B13: 代码：GitHub仓库或压缩后的项目目录
A14: 2 | B14: README：怎么安装、怎么运行、怎么测试
A15: 3 | B15: 你自己的设计说明：为什么这么设计
A16: 4 | B16: 测试结果：pytest / eval / demo
A17: 5 | B17: 你卡住的问题：定位到具体函数/概念，而不是只说“不会”
A18: 6 | B18: 希望我重点 Review：架构 / Python / LLM / RAG / Agent / 工程化

Sheet V2.1_八斗融合评估
A1: V2.1 · 八斗学院课程大纲融合评估
A2: 原则：不把八斗 5 阶段、11 项目全部塞入主线；按 LLM 应用开发岗位的就业价值拆分为“吸收进主线 / 作为实验 / 后置加分 / 暂缓”。
A4: 阶段/主题 | B4: 八斗核心内容 | C4: 优先级 | D4: V2.1处理 | E4: 安排周 | F4: 学习深度 | G4: 原因/面试价值 | H4: 验收方式
A5: 基础/表示学习 | B5: Embedding、Pooling、Norm、Dropout、Adam | C5: 🟠重点 | D5: 吸收 | E5: 2-3 | F5: 能解释 + 能做小实验 | G5: 帮助理解 Embedding/训练稳定性，但不走训练工程路线 | H5: 20句 embedding + pooling/normalization 实验
A6: 基础/Token | B6: Token、BPE分词 | C6: 🔴必学 | D6: 吸收 | E6: 2 | F6: 能解释 + 能观察 | G6: 直接影响上下文、成本与切分，是 LLM 应用基础 | H6: 能解释文本→token→模型输入
A7: Transformer | B7: Self-Attention、Encoder/Decoder、BERT | C7: 🟠重点 | D7: 吸收 | E7: 2/14 | F7: 能画图 + 能用自己的话解释 | G7: 面试常问；建立 LLM 原理底座 | H7: 画 QKV + Attention 流程并口述
A8: 传统 NLP | B8: BERT 分类、NER、CRF、Viterbi | C8: 🟡选学 | D8: 实验/回查 | E8: 14（面试） | F8: 跑通 + 知道用途 | G8: 对应用岗位不是主战，但可理解传统 NLP 与 LLM 的差别 | H8: 任选 1 个任务跑通并说清优缺点
A9: 语义匹配 | B9: Sentence-BERT、CrossEncoder、FAISS | C9: 🟠重点 | D9: 吸收 | E9: 3-5 | F9: 能解释 + 做检索实验 | G9: 直接连接 Embedding Retrieval 与 Rerank | H9: Dense vs CrossEncoder 对比实验
A10: RAG | B10: 文档解析、语义分块、混合检索、重排、RAGAS、查询改写 | C10: 🔴必学 | D10: 完整吸收 | E10: 3-6 | F10: 独立实现 + 优化 + 评测 | G10: 核心就业能力 | H10: 100-300条评测集 + 3轮优化
A11: Tool Calling | B11: Function Call / MCP / CLI 三方案 | C11: 🔴必学 | D11: 完整吸收 | E11: 7/9 | F11: 能手写 loop + 对比架构 | G11: 面试常问，也是 Agent 的基础 | H11: 完成同一工具的 FC / MCP 两种接入
A12: ReAct | B12: Reason→Action→Observation→Answer | C12: 🟠重点 | D12: 补充进主线 | E12: 7 | F12: 能手写机制 + 解释局限 | G12: 让你真正理解 Agent 决策循环 | H12: 手写最小 ReAct Agent
A13: Memory | B13: 四层记忆、压缩、定时自主调度 | C13: 🟠重点 | D13: 吸收核心思想 | E13: 8 | F13: 能设计 + 能解释 | G13: 是 Agent 长期运行的关键 | H13: 实现短期/长期两层记忆 + 压缩策略
A14: vLLM | B14: PagedAttention、量化、约束解码、多引擎 | C14: 🟠重点 | D14: 加深 | E14: 12 | F14: 会部署 + 解释定位 | G14: 模型服务能力是高级应用岗位加分项 | H14: 本地/服务器启动 vLLM + OpenAI-compatible API
A15: 高阶 Agent | B15: 自进化、Generate-Verify-Filter、DSPy | C15: 🟡选学 | D15: 后置加分 | E15: 13/14 | F15: 看懂架构 + 小实验 | G15: 高级能力，不能挤占求职主线 | H15: 写一页设计说明，不要求生产级
... A20: 工程稳定性 | B20: LLM API 故障转移、健康检测、监控点 | C20: 🔴必学 | D20: 新增独立工程实验 | E20: 10 | F20: 能实现 + 故障注入 | G20: 真实生产环境常见；弥补传统课程工程化不足 | H20: 超时→重试→fallback→health check 故障演练

Sheet V2.1_项目映射
A1: V2.1 · 八斗 11 个实战项目 → 我们的学习体系映射
A2: 判断标准：项目不是“做过就算”，而是看能否独立解释、修改、测试、定位问题；核心项目必须进入 GitHub 作品集。
A4: 八斗项目 | B4: 主要能力 | C4: V2.1归类 | D4: 对应我方模块 | E4: 执行周 | F4: 建议动作 | G4: 必须产出 | H4: Review重点 | I4: 简历用途 | J4: 状态
A5: 1 LLM流式聊天Web | B5: LLM API、SSE、Flask/服务 | C5: 必做 | D5: 项目1 LLM Chat API | E5: 1-2 | F5: 完整吸收并用 FastAPI 重写 | G5: 可运行 API + SSE + 测试 + README | H5: API设计、async、SSE、错误处理 | I5: 基础项目 | J5: 未开始
A6: 2 API故障转移与健康检测 | B6: 断路器、故障切换、健康探针 | C6: 必做 | D6: 工程稳定性实验 | E6: 10 | F6: 新增独立实验 | G6: failure injection + fallback + health check | H6: 重试边界、幂等、降级、恢复 | I6: 强加分 | J6: 未开始
A7: 3 中文文本分类 | B7: BERT/LLM/LoRA | C7: 实验 | D7: 传统NLP/微调认知 | E7: 14/课后 | F7: 二选一小实验 | G7: 模型对比+结论 | H7: BERT vs LLM vs LoRA | I7: 面试辅助 | J7: 未开始
A8: 4 中文NER | B8: BERT+CRF+Viterbi / LLM | C8: 实验 | D8: 传统NLP认知 | E8: 14/课后 | F8: 跑通一种方案即可 | G8: 小数据集+结果 | H8: BIO/CRF 与 LLM 提取差异 | I8: 面试辅助 | J8: 未开始
A9: 5 语义文本匹配 | B9: Bi-Encoder/CrossEncoder/FAISS | C9: 重点实验 | D9: Embedding+Rerank | E9: 3-5 | F9: 做检索/排序对比 | G9: Recall/Precision + 排序结果 | H9: 为什么二阶段检索 | I9: 核心技术证据 | J9: 未开始
A10: 6 vLLM私有化推理与约束解码 | B10: vLLM/PagedAttention/量化 | C10: 重点工程 | D10: 模型服务 | E10: 12 | F10: 部署并接入 Gateway | G10: 启动脚本+API+性能记录 | H10: TTFT/TPOT、并发、OpenAI兼容 | I10: 强加分 | J10: 未开始
A11: 7 年报企业级RAG问答 | B11: 多模态PDF、分层分块、Hybrid、RAGAS | C11: 核心项目 | D11: Production RAG | E11: 3-6 | F11: 作为企业知识库主项目的数据场景 | G11: 完整RAG + 评测报告 | H11: 召回、重排、证据链 | I11: 旗舰候选 | J11: 未开始
A12: 8 FC/MCP/CLI对比 | B12: 工具接入方式 | C12: 必做实验 | D12: Tool Calling + MCP | E12: 7/9 | F12: 同一工具做两种接入 | G12: 对比表 + demo | H12: 边界、复用、安全 | I12: 面试加分 | J12: 未开始
A13: 9 ReAct金融多轮Agent | B13: ReAct、Action-Observation | C13: 核心项目 | D13: Agent/LangGraph | E13: 7-8 | F13: 抽象成通用企业Agent | G13: workflow图+失败案例 | H13: Agent vs Workflow | I13: 核心项目 | J13: 未开始
A14: 10 四层记忆与自主调度 | B14: Memory、压缩、定时调度 | C14: 重点实验 | D14: Agent Memory | E14: 8 | F14: 只实现必要两层记忆+调度 | G14: 设计文档+demo | H14: 记忆写入/召回/压缩 | I14: 加分 | J14: 未开始
A15: 11 自进化Skill Agent | B15: Skill、自我评估、迭代闭环 | C15: 后置加分 | D15: 高级Agent/Skill | E15: 13-14 | F15: 小实验/架构设计，不做大项目 | G15: 设计图+最小demo | H15: Evaluation闭环与安全边界 | I15: 强加分 | J15: 未开始

Sheet V2.1_能力验收矩阵
A1: V2.1 · LLM Application Engineer 能力验收矩阵
A2: 毕业不是“看完视频”，而是每项能力都有证据：代码 / 实验 / 项目 / 面试四类证据。达到“毕业门槛”后才算通过。
A4: 能力域 | B4: 能力点 | C4: 级别 | D4: 知识要求 | E4: 代码证据 | F4: 实验/数据证据 | G4: 项目证据 | H4: 面试追问 | I4: 毕业门槛
A5: Python后端 | B5: asyncio/async/await/httpx | C5: 🔴必学 | D5: 理解 event loop、IO 等待、timeout | E5: 能写 async API 与并发请求 | F5: 10次并发/超时实验 | G5: 项目中使用 async client | H5: async 为什么能提高 IO 场景吞吐？ | I5: 可解释 + 可排障
A6: Python后端 | B6: FastAPI/Pydantic/SSE | C6: 🔴必学 | D6: 请求校验、依赖注入、Streaming | E6: 独立写 /chat /health /stream | F6: 异常/断开/心跳实验 | G6: 项目1与旗舰 | H6: SSE 与 WebSocket 何时选？ | I6: 90分钟独立写核心版
A7: LLM | B7: Token/Context/参数 | C7: 🔴必学 | D7: token、context window、temperature 等 | E7: 调用API并统计token | F7: 参数变化对输出实验 | G7: 模型Gateway | H7: temperature 为什么不是“更聪明”？ | I7: 能准确解释
A8: LLM | B8: Transformer/Attention | C8: 🟠重点 | D8: QKV、Self-Attention、Position | E8: 能读并修改简单 attention 示例 | F8: 可视化/小实验 | G8: 旗舰技术说明 | H8: 为什么要QKV？为什么需要位置编码？ | I8: 3分钟讲清
A9: LLM | B9: Structured Output | C9: 🔴必学 | D9: Schema、验证、失败重试 | E9: Pydantic结构化输出 | F9: 坏JSON/重试实验 | G9: 内容分析服务 | H9: 如何保证 JSON 稳定？ | I9: 可落地
A10: RAG | B10: Embedding/Similarity/TopK | C10: 🔴必学 | D10: 向量、归一化、cosine/dot | E10: 手写top-k | F10: 不同embedding/距离实验 | G10: RAG Lab | H10: 归一化后为什么 dot≈cosine？ | I10: 能手写+解释
A11: RAG | B11: Chunk/Parsing/Metadata | C11: 🔴必学 | D11: 分块策略、来源、页码、权限 | E11: 实现 ingestion | F11: 3种chunk对比 | G11: 企业知识库 | H11: chunk太大/太小会怎样？ | I11: 能定位召回问题
A12: RAG | B12: Hybrid/Rerank/Query Rewrite | C12: 🟠重点 | D12: Dense+BM25、二阶段排序、查询改写 | E12: 实现并接入 | F12: 3轮实验及指标 | G12: Production RAG | H12: Rerank 为什么不是多此一举？ | I12: 有数据证明收益
A13: RAG | B13: Evaluation/Regression | C13: 🟠重点 | D13: dataset、Recall/Precision、groundedness | E13: 自动评测脚本 | F13: 100-300条评测集 | G13: 旗舰项目回归 | H13: 如何判断一次优化真的有效？ | I13: 可重复跑
A14: Agent | B14: Tool Calling | C14: 🔴必学 | D14: schema、arguments、tool result loop | E14: 不依赖框架手写loop | F14: 正常/错误tool分支 | G14: Agent项目 | H14: 模型如何决定调用哪个工具？ | I14: 独立实现
A15: Agent | B15: ReAct/Workflow | C15: 🟠重点 | D15: Reason-Action-Observation、固定图 | E15: 最小ReAct + workflow | F15: 失败案例对比 | G15: Agent项目 | H15: 什么时候不用Agent？ | I15: 能做架构选择
... A23: 求职 | B23: 项目/系统设计/表达 | C23: 🔴必学 | D23: STAR、trade-off、量化指标 | E23: README/架构图 | F23: 评测报告 | G23: 旗舰项目 | H23: 为什么选A不选B？ | I23: 30分钟完整答辩
